<?xml version="1.0" encoding="utf-8"?>
<!-- This URDF was automatically created by SolidWorks to URDF Exporter! Originally created by Stephen Brawner (brawner@gmail.com) 
     Commit Version: 1.6.0-4-g7f85cfe  Build Version: 1.6.7995.38578
     For more information, please see http://wiki.ros.org/sw_urdf_exporter -->
<robot
  name="Carver_Simulation">
  <link
    name="base_link">
    <inertial>
      <origin
        xyz="-0.0165693433496452 0.00383942634735183 -0.000817493161058267"
        rpy="0 0 0" />
      <mass
        value="37.371684470221" />
      <inertia
        ixx="2.94202764307074"
        ixy="0.00865760497952898"
        ixz="0.0601337623044526"
        iyy="10.9291458319131"
        iyz="0.000101372386923447"
        izz="13.2592926130001" />
    </inertial>
    <visual>
      <origin
        xyz="0 0 0"
        rpy="0 0 0" />
      <geometry>
        <mesh
          filename="package://modelo_robot/meshes/base_link.STL" />
      </geometry>
      <material
        name="">
        <color
          rgba="0.792156862745098 0.819607843137255 0.933333333333333 1" />
      </material>
    </visual>
    <collision>
      <origin
        xyz="0 0 0"
        rpy="0 0 0" />
      <geometry>
        <mesh
          filename="package://modelo_robot/meshes/base_link.STL" />
      </geometry>
    </collision>
  </link>
  <link
    name="Hand">
    <inertial>
      <origin
        xyz="-0.0163697327965882 -0.0114067195760359 0.0137925030988115"
        rpy="0 0 0" />
      <mass
        value="0.60924910581716" />
      <inertia
        ixx="0.0172502548434045"
        ixy="-8.65184450644734E-05"
        ixz="2.57650399891012E-05"
        iyy="0.00174095337115687"
        iyz="8.39246317800817E-06"
        izz="0.018849059783654" />
    </inertial>
    <visual>
      <origin
        xyz="0 0 0"
        rpy="0 0 0" />
      <geometry>
        <mesh
          filename="package://modelo_robot/meshes/Hand.STL" />
      </geometry>
      <material
        name="">
        <color
          rgba="0.792156862745098 0.819607843137255 0.933333333333333 1" />
      </material>
    </visual>
    <collision>
      <origin
        xyz="0 0 0"
        rpy="0 0 0" />
      <geometry>
        <mesh
          filename="package://modelo_robot/meshes/Hand.STL" />
      </geometry>
    </collision>
  </link>
  <joint
    name="Hand"
    type="revolute">
    <origin
      xyz="-0.8089 -0.0133 0.945"
      rpy="0 0 -3.0131" />
    <parent
      link="base_link" />
    <child
      link="Hand" />
    <axis
      xyz="0 0 -1" />
    <limit
      lower="-1.57079632679"
      upper="1.57079632679"
      effort="0"
      velocity="0" />
  </joint>
  <link
    name="Caster">
    <inertial>
      <origin
        xyz="0 -9.43473255992894E-17 -0.104775587726131"
        rpy="0 0 0" />
      <mass
        value="0.193424777960769" />
      <inertia
        ixx="0.0014025581760965"
        ixy="2.50052886906149E-05"
        ixz="-1.44817994119794E-19"
        iyy="0.000934524386055236"
        iyz="-6.65058343506944E-19"
        izz="0.000520235989765606" />
    </inertial>
    <visual>
      <origin
        xyz="0 0 0"
        rpy="0 0 0" />
      <geometry>
        <mesh
          filename="package://modelo_robot/meshes/Caster.STL" />
      </geometry>
      <material
        name="">
        <color
          rgba="0.792156862745098 0.819607843137255 0.933333333333333 1" />
      </material>
    </visual>
    <collision>
      <origin
        xyz="0 0 0"
        rpy="0 0 0" />
      <geometry>
        <mesh
          filename="package://modelo_robot/meshes/Caster.STL" />
      </geometry>
    </collision>
  </link>
  <joint
    name="Caster"
    type="revolute">
    <origin
      xyz="-0.5575 0 -0.075"
      rpy="0 0 3.1416" />
    <parent
      link="base_link" />
    <child
      link="Caster" />
    <axis
      xyz="0 0 1" />
    <limit
      lower="-1.57079632679"
      upper="1.57079632679"
      effort="0"
      velocity="0" />
  </joint>
  <link
    name="Front_Wheel">
    <inertial>
      <origin
        xyz="0 0 -9.87142072128186E-18"
        rpy="0 0 0" />
      <mass
        value="3.12687627273034" />
      <inertia
        ixx="0.0180225780012183"
        ixy="2.49020474755959E-19"
        ixz="-0.000899856132012397"
        iyy="0.0179746385139624"
        iyz="5.11486813332503E-18"
        izz="0.0348655379513552" />
    </inertial>
    <visual>
      <origin
        xyz="0 0 0"
        rpy="0 0 0" />
      <geometry>
        <mesh
          filename="package://modelo_robot/meshes/Front_Wheel.STL" />
      </geometry>
      <material
        name="">
        <color
          rgba="0.792156862745098 0.819607843137255 0.933333333333333 1" />
      </material>
    </visual>
    <collision>
      <origin
        xyz="0 0 0"
        rpy="0 0 0" />
      <geometry>
        <mesh
          filename="package://modelo_robot/meshes/Front_Wheel.STL" />
      </geometry>
    </collision>
  </link>
  <joint
    name="Front_Wheel"
    type="continuous">
    <origin
      xyz="0 0 -0.19"
      rpy="-1.5708 0 0" />
    <parent
      link="Caster" />
    <child
      link="Front_Wheel" />
    <axis
      xyz="0 0 -1" />
  </joint>
  <link
    name="Left_Wheel">
    <inertial>
      <origin
        xyz="1.11022302462516E-16 0 -0.0106289786705237"
        rpy="0 0 0" />
      <mass
        value="7.06100394665823" />
      <inertia
        ixx="0.0674525928695192"
        ixy="-7.86224832473996E-18"
        ixz="7.3950420460897E-19"
        iyy="0.0674525928695192"
        iyz="3.10925130132762E-19"
        izz="0.127189460779996" />
    </inertial>
    <visual>
      <origin
        xyz="0 0 0"
        rpy="0 0 0" />
      <geometry>
        <mesh
          filename="package://modelo_robot/meshes/Left_Wheel.STL" />
      </geometry>
      <material
        name="">
        <color
          rgba="0.792156862745098 0.819607843137255 0.933333333333333 1" />
      </material>
    </visual>
    <collision>
      <origin
        xyz="0 0 0"
        rpy="0 0 0" />
      <geometry>
        <mesh
          filename="package://modelo_robot/meshes/Left_Wheel.STL" />
      </geometry>
    </collision>
  </link>
  <joint
    name="Left_Wheel"
    type="continuous">
    <origin
      xyz="0.5995 -0.3775 -0.23467"
      rpy="-1.5708 0 3.1416" />
    <parent
      link="base_link" />
    <child
      link="Left_Wheel" />
    <axis
      xyz="0 0 -1" />
  </joint>
  <link
    name="Right_Wheel">
    <inertial>
      <origin
        xyz="0 -2.77555756156289E-17 -0.0106289786705236"
        rpy="0 0 0" />
      <mass
        value="7.06100394665823" />
      <inertia
        ixx="0.0674525928695192"
        ixy="-1.08420198492021E-33"
        ixz="1.07496044377481E-19"
        iyy="0.0674525928695193"
        iyz="-6.1125706242759E-34"
        izz="0.127189460779996" />
    </inertial>
    <visual>
      <origin
        xyz="0 0 0"
        rpy="0 0 0" />
      <geometry>
        <mesh
          filename="package://modelo_robot/meshes/Right_Wheel.STL" />
      </geometry>
      <material
        name="">
        <color
          rgba="0.792156862745098 0.819607843137255 0.933333333333333 1" />
      </material>
    </visual>
    <collision>
      <origin
        xyz="0 0 0"
        rpy="0 0 0" />
      <geometry>
        <mesh
          filename="package://modelo_robot/meshes/Right_Wheel.STL" />
      </geometry>
    </collision>
  </link>
  <joint
    name="Right_Wheel"
    type="continuous">
    <origin
      xyz="0.5995 0.3775 -0.23467"
      rpy="1.5708 0 3.1416" />
    <parent
      link="base_link" />
    <child
      link="Right_Wheel" />
    <axis
      xyz="0 0 -1" />
  </joint>
</robot>